<?xml version="1.0" ?>
<robot name="spot" xmlns:xacro="http://www.ros.org/wiki/xacro">

    <!-- We do not specify links for the cameras in the URDF. Instead, transforms for those are
         published by the driver (see spot_driver package) during runtime, so that the transforms
         include calibration adjustments. -->

    <xacro:arg name="has_arm" default="False" />
    <xacro:arg name="has_eap" default="False" />

    <!-- Fixed links -->
    <link name="body">
        <visual>
            <geometry>
                <mesh filename="package://spot_description/meshes/body/body.dae" />
            </geometry>
        </visual>
        <collision>
            <geometry>
                <mesh filename="package://spot_description/meshes/body/body_collision.stl" />
            </geometry>
        </collision>
        <inertial>
             <mass value="16.25" />
             <inertia  ixx="0.085" ixy="0.0"  ixz="0.0"  iyy="1.045"  iyz="0.0"  izz="1.042" />
    	</inertial>
    </link>

    <link name="base_link"/>
    <joint name="base_link_joint" type="fixed">
        <origin xyz="0 0 0" rpy="0 0 0" />
        <parent link="body" />
        <child link="base_link" />
    </joint>

    <link name="front_rail"/>
    <joint name="front_rail_joint" type="fixed">
        <origin xyz="0.223 0 0.0805" rpy="0 0 0" />
        <parent link="body" />
        <child link="front_rail" />
    </joint>

    <link name="rear_rail"/>
    <joint name="rear_rail_joint" type="fixed">
        <origin xyz="-0.223 0 0.0805" rpy="0 0 0" />
        <parent link="body" />
        <child link="rear_rail" />
    </joint>

    <!-- Front Left -->
    <link name="front_left_hip">
        <visual>
            <geometry>
                <mesh filename="package://spot_description/meshes/body/front_left_hip.dae" />
            </geometry>
        </visual>
        <collision>
            <geometry>
                <mesh filename="package://spot_description/meshes/body/front_left_hip_collision.stl" />
            </geometry>
        </collision>
        <inertial>
            <mass value="1.5" />
    	    <inertia  ixx="0.0605" ixy="0.0"  ixz="0.0"  iyy="0.0"  iyz="0.0"  izz="0.0" />
    	</inertial>
    </link>
    <joint name="front_left_hip_x" type="revolute">
        <origin xyz="0.29785 0.05500 0.00000" rpy="0 0 0" />
        <axis xyz="1 0 0" />
        <parent link="body" />
        <child link="front_left_hip" />
        <dynamics damping="0.1" friction="0.1"/>
        <limit effort="1000" velocity="1000.00" lower="-0.78539816339744827899" upper="0.78539816339744827899" />
    </joint>
    <transmission name="front_left_hip_x_trans">
	    <type>transmission_interface/SimpleTransmission</type>
	    <joint name="front_left_hip_x">
            <hardwareInterface>EffortJointInterface</hardwareInterface>
        </joint>
	    <actuator name="front_left_hip_x">
          	<mechanicalReduction>50</mechanicalReduction>
          	<hardwareInterface>EffortJointInterface</hardwareInterface>
	    </actuator>
    </transmission>

    <link name="front_left_upper_leg">
        <visual>
            <geometry>
                <mesh filename="package://spot_description/meshes/body/front_left_upper_leg.dae" />
            </geometry>
        </visual>
        <collision>
            <geometry>
                <mesh filename="package://spot_description/meshes/body/front_left_upper_leg_collision.stl" />
            </geometry>
        </collision>
        <inertial>
            <mass value="1.5" />
    	    <inertia  ixx="0.0" ixy="0.0"  ixz="0.0"  iyy="0.05"  iyz="0.0"  izz="0.0" />
    	</inertial>
    </link>
    <joint name="front_left_hip_y" type="revolute">
        <origin xyz="0.0 0.110945 0.0" rpy="0 0 0" />
        <axis xyz="0 1 0" />
        <parent link="front_left_hip" />
        <child link="front_left_upper_leg" />
        <dynamics damping="0.1" friction="0.1"/>
        <limit effort="1000" velocity="1000.00" lower="-0.89884456477707963539" upper="2.2951079663725435509" />
    </joint>
    <transmission name="front_left_hip_y_trans">
        <type>transmission_interface/SimpleTransmission</type>
        <joint name="front_left_hip_y">
            <hardwareInterface>EffortJointInterface</hardwareInterface>
        </joint>
        <actuator name="front_left_hip_y">
            <mechanicalReduction>50</mechanicalReduction>
            <hardwareInterface>EffortJointInterface</hardwareInterface>
        </actuator>
    </transmission>

    <link name="front_left_lower_leg">
        <visual>
            <geometry>
                <mesh filename="package://spot_description/meshes/body/front_left_lower_leg.dae" />
            </geometry>
        </visual>
        <collision>
            <geometry>
                <mesh filename="package://spot_description/meshes/body/front_left_lower_leg_collision.stl" />
            </geometry>
        </collision>
        <inertial>
            <mass value="1.0" />
    	    <inertia  ixx="0.0" ixy="0.0"  ixz="0.0"  iyy="0.045"  iyz="0.0"  izz="0.0" />
    	</inertial>
    </link>
    <joint name="front_left_knee" type="revolute">
        <origin xyz="0.025 0.000 -0.3205" rpy="0 0 0" />
        <axis xyz="0 1 0" />
        <parent link="front_left_upper_leg" />
        <child link="front_left_lower_leg" />
        <dynamics damping="0.1" friction="0.1"/>
        <limit effort="1000" velocity="1000.00" lower="-2.7929" upper="-0.254801" />
    </joint>
    <gazebo reference="front_left_lower_leg">
        <sensor name="front_left_lower_leg_contactsensor_sensor" type="contact">
        <always_on>true</always_on>
        <contact>
            <collision>front_left_lower_leg_fixed_joint_lump__front_bump_sensor_collision</collision>
        </contact>
        <plugin filename="libgazebo_ros_bumper.so" name="front_left_lower_leg_plugin">
            <bumperTopicName>front_left_lower_leg_contact</bumperTopicName>
            <frameName>front_left_lower_leg</frameName>
        </plugin>
        </sensor>
    </gazebo>

    <transmission name="front_left_knee_trans">
	  <type>transmission_interface/SimpleTransmission</type>
	  <joint name="front_left_knee">
          	<hardwareInterface>EffortJointInterface</hardwareInterface>
      </joint>
	  <actuator name="front_left_knee">
          	<mechanicalReduction>50</mechanicalReduction>
          	<hardwareInterface>EffortJointInterface</hardwareInterface>
	  </actuator>
    </transmission>

    <!-- Front Right -->
    <link name="front_right_hip">
        <visual>
            <geometry>
                <mesh filename="package://spot_description/meshes/body/front_right_hip.dae" />
            </geometry>
        </visual>
        <collision>
            <geometry>
                <mesh filename="package://spot_description/meshes/body/front_right_hip_collision.stl" />
            </geometry>
        </collision>
        <inertial>
            <mass value="1.5" />
    	    <inertia  ixx="0.0605" ixy="0.0"  ixz="0.0"  iyy="0.0"  iyz="0.0"  izz="0.0" />
    	</inertial>
    </link>
    <joint name="front_right_hip_x" type="revolute">
        <origin xyz="0.29785 -0.05500 0.00000" rpy="0 0 0" />
        <axis xyz="1 0 0" />
        <parent link="body" />
        <child link="front_right_hip" />
        <dynamics damping="0.1" friction="0.1"/>
        <limit effort="1000" velocity="1000.00" lower="-0.78539816339744827899" upper="0.78539816339744827899" />
    </joint>
    <transmission name="front_right_hip_x_trans">
	  <type>transmission_interface/SimpleTransmission</type>
	  <joint name="front_right_hip_x">
          	<hardwareInterface>EffortJointInterface</hardwareInterface>
      </joint>
	  <actuator name="front_right_hip_x">
          	<mechanicalReduction>50</mechanicalReduction>
          	<hardwareInterface>EffortJointInterface</hardwareInterface>
	  </actuator>
    </transmission>

    <link name="front_right_upper_leg">
        <visual>
            <geometry>
                <mesh filename="package://spot_description/meshes/body/front_right_upper_leg.dae" />
            </geometry>
        </visual>
        <collision>
            <geometry>
                <mesh filename="package://spot_description/meshes/body/front_right_upper_leg_collision.stl" />
            </geometry>
        </collision>
        <inertial>
            <mass value="1.5" />
    	    <inertia  ixx="0.0" ixy="0.0"  ixz="0.0"  iyy="0.05"  iyz="0.0"  izz="0.0" />
    	</inertial>
    </link>
    <joint name="front_right_hip_y" type="revolute">
        <origin xyz="0.0 -0.110945 0.0" rpy="0 0 0" />
        <axis xyz="0 1 0" />
        <parent link="front_right_hip" />
        <child link="front_right_upper_leg" />
        <dynamics damping="0.1" friction="0.1"/>
        <limit effort="1000" velocity="1000.00" lower="-0.89884456477707963539" upper="2.2951079663725435509" />
    </joint>
    <transmission name="front_right_hip_y_trans">
        <type>transmission_interface/SimpleTransmission</type>
        <joint name="front_right_hip_y">
            <hardwareInterface>EffortJointInterface</hardwareInterface>
        </joint>
        <actuator name="front_right_hip_y">
            <mechanicalReduction>50</mechanicalReduction>
            <hardwareInterface>EffortJointInterface</hardwareInterface>
        </actuator>
    </transmission>

    <link name="front_right_lower_leg">
        <visual>
            <geometry>
                <mesh filename="package://spot_description/meshes/body/front_right_lower_leg.dae" />
            </geometry>
        </visual>
        <collision>
            <geometry>
                <mesh filename="package://spot_description/meshes/body/front_right_lower_leg_collision.stl" />
            </geometry>
        </collision>
        <inertial>
            <mass value="1.0" />
    	    <inertia  ixx="0.0" ixy="0.0"  ixz="0.0"  iyy="0.045"  iyz="0.0"  izz="0.0" />
    	</inertial>
    </link>
    <joint name="front_right_knee" type="revolute">
        <origin xyz="0.025 0.000 -0.3205" rpy="0 0 0" />
        <axis xyz="0 1 0" />
        <parent link="front_right_upper_leg" />
        <child link="front_right_lower_leg" />
        <dynamics damping="0.1" friction="0.1"/>
        <limit effort="1000" velocity="1000.00" lower="-2.7929" upper="-0.247563" />
    </joint>
    <gazebo reference="front_right_lower_leg">
        <sensor name="front_right_lower_leg_contactsensor_sensor" type="contact">
        <always_on>true</always_on>
        <contact>
            <collision>front_right_lower_leg_fixed_joint_lump__front_bump_sensor_collision</collision>
        </contact>
        <plugin filename="libgazebo_ros_bumper.so" name="front_right_lower_leg_plugin">
            <bumperTopicName>front_right_lower_leg_contact</bumperTopicName>
            <frameName>front_right_lower_leg</frameName>
        </plugin>
        </sensor>
    </gazebo>

    <transmission name="front_right_knee_trans">
        <type>transmission_interface/SimpleTransmission</type>
        <joint name="front_right_knee">
            <hardwareInterface>EffortJointInterface</hardwareInterface>
        </joint>
        <actuator name="front_right_knee">
            <mechanicalReduction>50</mechanicalReduction>
            <hardwareInterface>EffortJointInterface</hardwareInterface>
        </actuator>
    </transmission>

    <!-- Rear Left -->
    <link name="rear_left_hip">
        <visual>
            <geometry>
                <mesh filename="package://spot_description/meshes/body/rear_left_hip.dae" />
            </geometry>
        </visual>
        <collision>
            <geometry>
                <mesh filename="package://spot_description/meshes/body/rear_left_hip_collision.stl" />
            </geometry>
        </collision>
        <inertial>
            <mass value="1.5" />
    	    <inertia  ixx="0.0605" ixy="0.0"  ixz="0.0"  iyy="0.0"  iyz="0.0"  izz="0.0" />
    	</inertial>
    </link>
    <joint name="rear_left_hip_x" type="revolute">
        <origin xyz="-0.29785 0.05500 0.00000" rpy="0 0 0" />
        <axis xyz="1 0 0" />
        <parent link="body" />
        <child link="rear_left_hip" />
        <dynamics damping="0.1" friction="0.1"/>
        <limit effort="1000" velocity="1000.00" lower="-0.78539816339744827899" upper="0.78539816339744827899" />
    </joint>
    <transmission name="rear_left_hip_x_trans">
        <type>transmission_interface/SimpleTransmission</type>
        <joint name="rear_left_hip_x">
            <hardwareInterface>EffortJointInterface</hardwareInterface>
        </joint>
        <actuator name="rear_left_hip_x">
            <mechanicalReduction>50</mechanicalReduction>
            <hardwareInterface>EffortJointInterface</hardwareInterface>
        </actuator>
    </transmission>

    <link name="rear_left_upper_leg">
        <visual>
            <geometry>
                <mesh filename="package://spot_description/meshes/body/rear_left_upper_leg.dae" />
            </geometry>
        </visual>
        <collision>
            <geometry>
                <mesh filename="package://spot_description/meshes/body/rear_left_upper_leg_collision.stl" />
            </geometry>
        </collision>
        <inertial>
           <mass value="1.5" />
    	   <inertia  ixx="0.0" ixy="0.0"  ixz="0.0"  iyy="0.05"  iyz="0.0"  izz="0.0" />
    	</inertial>
    </link>
    <joint name="rear_left_hip_y" type="revolute">
        <origin xyz="0.0 0.110945 0.0" rpy="0 0 0" />
        <axis xyz="0 1 0" />
        <parent link="rear_left_hip" />
        <child link="rear_left_upper_leg" />
        <dynamics damping="0.1" friction="0.1"/>
        <limit effort="1000" velocity="1000.00" lower="-0.89884456477707963539" upper="2.2951079663725435509" />
    </joint>
    <transmission name="rear_left_hip_y_trans">
        <type>transmission_interface/SimpleTransmission</type>
        <joint name="rear_left_hip_y">
            <hardwareInterface>EffortJointInterface</hardwareInterface>
        </joint>
        <actuator name="rear_left_hip_y">
            <mechanicalReduction>50</mechanicalReduction>
            <hardwareInterface>EffortJointInterface</hardwareInterface>
        </actuator>
    </transmission>

    <link name="rear_left_lower_leg">
        <visual>
            <geometry>
                <mesh filename="package://spot_description/meshes/body/rear_left_lower_leg.dae" />
            </geometry>
        </visual>
        <collision>
            <geometry>
                <mesh filename="package://spot_description/meshes/body/rear_left_lower_leg_collision.stl" />
            </geometry>
        </collision>
        <inertial>
            <mass value="1.0" />
    	    <inertia  ixx="0.0" ixy="0.0"  ixz="0.0"  iyy="0.045"  iyz="0.0"  izz="0.0" />
    	</inertial>
    </link>
    <joint name="rear_left_knee" type="revolute">
        <origin xyz="0.025 0.000 -0.3205" rpy="0 0 0" />
        <axis xyz="0 1 0" />
        <parent link="rear_left_upper_leg" />
        <child link="rear_left_lower_leg" />
        <dynamics damping="0.1" friction="0.1"/>
        <limit effort="1000" velocity="1000.00" lower="-2.7929" upper="-0.267153" />
    </joint>
    <gazebo reference="rear_left_lower_leg">
        <sensor name="rear_left_lower_leg_contactsensor_sensor" type="contact">
        <always_on>true</always_on>
        <contact>
            <collision>rear_left_lower_leg_fixed_joint_lump__rear_bump_sensor_collision</collision>
        </contact>
        <plugin filename="libgazebo_ros_bumper.so" name="rear_left_lower_leg_plugin">
            <bumperTopicName>rear_left_lower_leg_contact</bumperTopicName>
            <frameName>rear_left_lower_leg</frameName>
        </plugin>
        </sensor>
    </gazebo>
    <transmission name="rear_left_knee_trans">
        <type>transmission_interface/SimpleTransmission</type>
        <joint name="rear_left_knee">
             <hardwareInterface>EffortJointInterface</hardwareInterface>
        </joint>
        <actuator name="rear_left_knee">
            <mechanicalReduction>50</mechanicalReduction>
            <hardwareInterface>EffortJointInterface</hardwareInterface>
        </actuator>
    </transmission>

    <!-- Rear Right -->
    <link name="rear_right_hip">
        <visual>
            <geometry>
                <mesh filename="package://spot_description/meshes/body/rear_right_hip.dae" />
            </geometry>
        </visual>
        <collision>
            <geometry>
                <mesh filename="package://spot_description/meshes/body/rear_right_hip_collision.stl" />
            </geometry>
        </collision>
        <inertial>
            <mass value="1.5" />
    	    <inertia  ixx="0.0605" ixy="0.0"  ixz="0.0"  iyy="0.0"  iyz="0.0"  izz="0.0" />
    	</inertial>
    </link>
    <joint name="rear_right_hip_x" type="revolute">
        <origin xyz="-0.29785 -0.05500 0.00000" rpy="0 0 0" />
        <axis xyz="1 0 0" />
        <parent link="body" />
        <child link="rear_right_hip" />
        <dynamics damping="0.1" friction="0.1"/>
        <limit effort="1000" velocity="1000.00" lower="-0.78539816339744827899" upper="0.78539816339744827899" />
    </joint>
    <transmission name="rear_right_hip_x_trans">
        <type>transmission_interface/SimpleTransmission</type>
        <joint name="rear_right_hip_x">
            <hardwareInterface>EffortJointInterface</hardwareInterface>
        </joint>
        <actuator name="rear_right_hip_x">
            <mechanicalReduction>50</mechanicalReduction>
            <hardwareInterface>EffortJointInterface</hardwareInterface>
        </actuator>
    </transmission>
    <link name="rear_right_upper_leg">
        <visual>
            <geometry>
                <mesh filename="package://spot_description/meshes/body/rear_right_upper_leg.dae" />
            </geometry>
        </visual>
        <collision>
            <geometry>
                <mesh filename="package://spot_description/meshes/body/rear_right_upper_leg_collision.stl" />
            </geometry>
        </collision>
        <inertial>
            <mass value="1.5" />
    	    <inertia  ixx="0.0" ixy="0.0"  ixz="0.0"  iyy="0.05"  iyz="0.0"  izz="0.0" />
    	</inertial>
    </link>
    <joint name="rear_right_hip_y" type="revolute">
        <origin xyz="0.0 -0.110945 0.0" rpy="0 0 0" />
        <axis xyz="0 1 0" />
        <parent link="rear_right_hip" />
        <child link="rear_right_upper_leg" />
        <dynamics damping="0.1" friction="0.1"/>
        <limit effort="1000" velocity="1000.00" lower="-0.89884456477707963539" upper="2.2951079663725435509" />
    </joint>
    <transmission name="rear_right_hip_y_trans">
        <type>transmission_interface/SimpleTransmission</type>
        <joint name="rear_right_hip_y">
            <hardwareInterface>EffortJointInterface</hardwareInterface>
            </joint>
        <actuator name="rear_right_hip_y">
            <mechanicalReduction>50</mechanicalReduction>
            <hardwareInterface>EffortJointInterface</hardwareInterface>
        </actuator>
    </transmission>
    <link name="rear_right_lower_leg">
        <visual>
            <geometry>
                <mesh filename="package://spot_description/meshes/body/rear_right_lower_leg.dae" />
            </geometry>
        </visual>
        <collision>
            <geometry>
                <mesh filename="package://spot_description/meshes/body/rear_right_lower_leg_collision.stl" />
            </geometry>
        </collision>
        <inertial>
            <mass value="1.0" />
    	    <inertia  ixx="0.0" ixy="0.0"  ixz="0.0"  iyy="0.045"  iyz="0.0"  izz="0.0" />
    	</inertial>
    </link>
    <joint name="rear_right_knee" type="revolute">
        <origin xyz="0.025 0.000 -0.3205" rpy="0 0 0" />
        <axis xyz="0 1 0" />
        <parent link="rear_right_upper_leg" />
        <child link="rear_right_lower_leg" />
        <dynamics damping="0.1" friction="0.1"/>
        <limit effort="1000" velocity="1000.00" lower="-2.7929" upper="-0.257725" />
    </joint>
    <gazebo reference="rear_right_lower_leg">
        <sensor name="rear_right_lower_leg_contactsensor_sensor" type="contact">
        <always_on>true</always_on>
        <contact>
            <collision>rear_right_lower_leg_fixed_joint_lump__rear_bump_sensor_collision</collision>
        </contact>
        <plugin filename="libgazebo_ros_bumper.so" name="rear_right_lower_leg_plugin">
            <bumperTopicName>rear_right_lower_leg_contact</bumperTopicName>
            <frameName>rear_right_lower_leg</frameName>
        </plugin>
        </sensor>
    </gazebo>
    <transmission name="rear_right_knee_trans">
        <type>transmission_interface/SimpleTransmission</type>
        <joint name="rear_right_knee">
            <hardwareInterface>EffortJointInterface</hardwareInterface>
            </joint>
        <actuator name="rear_right_knee">
            <mechanicalReduction>50</mechanicalReduction>
            <hardwareInterface>EffortJointInterface</hardwareInterface>
        </actuator>
    </transmission>

    <gazebo>
    	<plugin name="gazebo_ros_control" filename="libgazebo_ros_control.so"/>
    </gazebo>

    <!-- Spot Arm -->
    <xacro:if value="$(arg has_arm)">
        <xacro:include filename="$(find spot_description)/urdf/arm/spot_arm.urdf.xacro"/> 
        <xacro:spot_arm name="arm0"/>

        <joint name="arm0_mount" type="fixed">
            <origin xyz="0.292 0 0.188" rpy="0 0 0"/>
            <parent link="base_link"/>
            <child link="arm0_base_link"/>
        </joint>
    </xacro:if>

    <!-- Spot Enhanced Autonomy package (EAP) -->
    <xacro:if value="$(arg has_eap)">
        <link name="lidar_assembly">
            <visual>
                <geometry>
                    <mesh filename="package://spot_description/meshes/accessories/eap_lidar.stl" />
                </geometry>
            </visual>
            <collision>
                <geometry>
                    <mesh filename="package://spot_description/meshes/accessories/eap_lidar.stl" />
                </geometry>
            </collision>
        </link>
        <joint name="lidar_mount" type="fixed">
            <origin xyz="-0.03 0.0 0.0" rpy="0 0 0" />
            <parent link="rear_rail" />
            <child link="lidar_assembly" />
        </joint>

        <xacro:include filename="$(find velodyne_description)/urdf/VLP-16.urdf.xacro"/> 
        <xacro:VLP-16 parent="lidar_assembly" name="velodyne">
            <origin xyz="0.0 0 0.08" rpy="0 0 0" />
        </xacro:VLP-16>
    </xacro:if>

    <xacro:include filename="$(find spot_description)/urdf/realsense_mount.urdf.xacro"/>
    <xacro:realsense_mount parent = "arm0_wrist_roll">
        <origin xyz = "0.145 0 -0.06" rpy = "3.1416 0 -1.57"/>
    </xacro:realsense_mount>

    <!-- Optional custom includes. -->
    <xacro:include filename="$(optenv SPOT_URDF_EXTRAS empty.urdf)" />
</robot>
