<?xml version="1.0" ?>
<!-- =================================================================================== -->
<!-- |    This document was autogenerated by xacro from /home/caleb/ros2_ws/install/spot_description/share/spot_description/urdf/spot_with_arm.urdf.xacro | -->
<!-- |    EDITING THIS FILE BY HAND IS NOT RECOMMENDED                                 | -->
<!-- =================================================================================== -->
<robot name="spot">
  <!-- We do not specify links for the cameras in the URDF. Instead, transforms for those are
         published by the driver (see spot_driver package) during runtime, so that the transforms
         include calibration adjustments. -->
  <!-- Fixed links -->
  <link name="body">
    <visual>
      <geometry>
        <mesh filename="package://spot_description/meshes/body/body.dae"/>
      </geometry>
    </visual>
    <collision>
      <geometry>
        <mesh filename="package://spot_description/meshes/body/body_collision.stl"/>
      </geometry>
    </collision>
    <inertial>
      <mass value="16.25"/>
      <inertia ixx="0.085" ixy="0.0" ixz="0.0" iyy="1.045" iyz="0.0" izz="1.042"/>
    </inertial>
  </link>
  <link name="base_link"/>
  <joint name="base_link_joint" type="fixed">
    <origin rpy="0 0 0" xyz="0 0 0"/>
    <parent link="body"/>
    <child link="base_link"/>
  </joint>
  <link name="front_rail"/>
  <joint name="front_rail_joint" type="fixed">
    <origin rpy="0 0 0" xyz="0.223 0 0.0805"/>
    <parent link="body"/>
    <child link="front_rail"/>
  </joint>
  <link name="rear_rail"/>
  <joint name="rear_rail_joint" type="fixed">
    <origin rpy="0 0 0" xyz="-0.223 0 0.0805"/>
    <parent link="body"/>
    <child link="rear_rail"/>
  </joint>
  <!-- Front Left -->
  <link name="front_left_hip">
    <visual>
      <geometry>
        <mesh filename="package://spot_description/meshes/body/front_left_hip.dae"/>
      </geometry>
    </visual>
    <collision>
      <geometry>
        <mesh filename="package://spot_description/meshes/body/front_left_hip_collision.stl"/>
      </geometry>
    </collision>
    <inertial>
      <mass value="1.5"/>
      <inertia ixx="0.0605" ixy="0.0" ixz="0.0" iyy="0.0" iyz="0.0" izz="0.0"/>
    </inertial>
  </link>
  <joint name="front_left_hip_x" type="revolute">
    <origin rpy="0 0 0" xyz="0.29785 0.05500 0.00000"/>
    <axis xyz="1 0 0"/>
    <parent link="body"/>
    <child link="front_left_hip"/>
    <dynamics damping="0.1" friction="0.1"/>
    <limit effort="1000" lower="-0.78539816339744827899" upper="0.78539816339744827899" velocity="1000.00"/>
  </joint>
  <transmission name="front_left_hip_x_trans">
    <type>transmission_interface/SimpleTransmission</type>
    <joint name="front_left_hip_x">
      <hardwareInterface>EffortJointInterface</hardwareInterface>
    </joint>
    <actuator name="front_left_hip_x">
      <mechanicalReduction>50</mechanicalReduction>
      <hardwareInterface>EffortJointInterface</hardwareInterface>
    </actuator>
  </transmission>
  <link name="front_left_upper_leg">
    <visual>
      <geometry>
        <mesh filename="package://spot_description/meshes/body/front_left_upper_leg.dae"/>
      </geometry>
    </visual>
    <collision>
      <geometry>
        <mesh filename="package://spot_description/meshes/body/front_left_upper_leg_collision.stl"/>
      </geometry>
    </collision>
    <inertial>
      <mass value="1.5"/>
      <inertia ixx="0.0" ixy="0.0" ixz="0.0" iyy="0.05" iyz="0.0" izz="0.0"/>
    </inertial>
  </link>
  <joint name="front_left_hip_y" type="revolute">
    <origin rpy="0 0 0" xyz="0.0 0.110945 0.0"/>
    <axis xyz="0 1 0"/>
    <parent link="front_left_hip"/>
    <child link="front_left_upper_leg"/>
    <dynamics damping="0.1" friction="0.1"/>
    <limit effort="1000" lower="-0.89884456477707963539" upper="2.2951079663725435509" velocity="1000.00"/>
  </joint>
  <transmission name="front_left_hip_y_trans">
    <type>transmission_interface/SimpleTransmission</type>
    <joint name="front_left_hip_y">
      <hardwareInterface>EffortJointInterface</hardwareInterface>
    </joint>
    <actuator name="front_left_hip_y">
      <mechanicalReduction>50</mechanicalReduction>
      <hardwareInterface>EffortJointInterface</hardwareInterface>
    </actuator>
  </transmission>
  <link name="front_left_lower_leg">
    <visual>
      <geometry>
        <mesh filename="package://spot_description/meshes/body/front_left_lower_leg.dae"/>
      </geometry>
    </visual>
    <collision>
      <geometry>
        <mesh filename="package://spot_description/meshes/body/front_left_lower_leg_collision.stl"/>
      </geometry>
    </collision>
    <inertial>
      <mass value="1.0"/>
      <inertia ixx="0.0" ixy="0.0" ixz="0.0" iyy="0.045" iyz="0.0" izz="0.0"/>
    </inertial>
  </link>
  <joint name="front_left_knee" type="revolute">
    <origin rpy="0 0 0" xyz="0.025 0.000 -0.3205"/>
    <axis xyz="0 1 0"/>
    <parent link="front_left_upper_leg"/>
    <child link="front_left_lower_leg"/>
    <dynamics damping="0.1" friction="0.1"/>
    <limit effort="1000" lower="-2.7929" upper="-0.254801" velocity="1000.00"/>
  </joint>
  <gazebo reference="front_left_lower_leg">
    <sensor name="front_left_lower_leg_contactsensor_sensor" type="contact">
      <always_on>true</always_on>
      <contact>
        <collision>front_left_lower_leg_fixed_joint_lump__front_bump_sensor_collision</collision>
      </contact>
      <plugin filename="libgazebo_ros_bumper.so" name="front_left_lower_leg_plugin">
        <bumperTopicName>front_left_lower_leg_contact</bumperTopicName>
        <frameName>front_left_lower_leg</frameName>
      </plugin>
    </sensor>
  </gazebo>
  <transmission name="front_left_knee_trans">
    <type>transmission_interface/SimpleTransmission</type>
    <joint name="front_left_knee">
      <hardwareInterface>EffortJointInterface</hardwareInterface>
    </joint>
    <actuator name="front_left_knee">
      <mechanicalReduction>50</mechanicalReduction>
      <hardwareInterface>EffortJointInterface</hardwareInterface>
    </actuator>
  </transmission>
  <!-- Front Right -->
  <link name="front_right_hip">
    <visual>
      <geometry>
        <mesh filename="package://spot_description/meshes/body/front_right_hip.dae"/>
      </geometry>
    </visual>
    <collision>
      <geometry>
        <mesh filename="package://spot_description/meshes/body/front_right_hip_collision.stl"/>
      </geometry>
    </collision>
    <inertial>
      <mass value="1.5"/>
      <inertia ixx="0.0605" ixy="0.0" ixz="0.0" iyy="0.0" iyz="0.0" izz="0.0"/>
    </inertial>
  </link>
  <joint name="front_right_hip_x" type="revolute">
    <origin rpy="0 0 0" xyz="0.29785 -0.05500 0.00000"/>
    <axis xyz="1 0 0"/>
    <parent link="body"/>
    <child link="front_right_hip"/>
    <dynamics damping="0.1" friction="0.1"/>
    <limit effort="1000" lower="-0.78539816339744827899" upper="0.78539816339744827899" velocity="1000.00"/>
  </joint>
  <transmission name="front_right_hip_x_trans">
    <type>transmission_interface/SimpleTransmission</type>
    <joint name="front_right_hip_x">
      <hardwareInterface>EffortJointInterface</hardwareInterface>
    </joint>
    <actuator name="front_right_hip_x">
      <mechanicalReduction>50</mechanicalReduction>
      <hardwareInterface>EffortJointInterface</hardwareInterface>
    </actuator>
  </transmission>
  <link name="front_right_upper_leg">
    <visual>
      <geometry>
        <mesh filename="package://spot_description/meshes/body/front_right_upper_leg.dae"/>
      </geometry>
    </visual>
    <collision>
      <geometry>
        <mesh filename="package://spot_description/meshes/body/front_right_upper_leg_collision.stl"/>
      </geometry>
    </collision>
    <inertial>
      <mass value="1.5"/>
      <inertia ixx="0.0" ixy="0.0" ixz="0.0" iyy="0.05" iyz="0.0" izz="0.0"/>
    </inertial>
  </link>
  <joint name="front_right_hip_y" type="revolute">
    <origin rpy="0 0 0" xyz="0.0 -0.110945 0.0"/>
    <axis xyz="0 1 0"/>
    <parent link="front_right_hip"/>
    <child link="front_right_upper_leg"/>
    <dynamics damping="0.1" friction="0.1"/>
    <limit effort="1000" lower="-0.89884456477707963539" upper="2.2951079663725435509" velocity="1000.00"/>
  </joint>
  <transmission name="front_right_hip_y_trans">
    <type>transmission_interface/SimpleTransmission</type>
    <joint name="front_right_hip_y">
      <hardwareInterface>EffortJointInterface</hardwareInterface>
    </joint>
    <actuator name="front_right_hip_y">
      <mechanicalReduction>50</mechanicalReduction>
      <hardwareInterface>EffortJointInterface</hardwareInterface>
    </actuator>
  </transmission>
  <link name="front_right_lower_leg">
    <visual>
      <geometry>
        <mesh filename="package://spot_description/meshes/body/front_right_lower_leg.dae"/>
      </geometry>
    </visual>
    <collision>
      <geometry>
        <mesh filename="package://spot_description/meshes/body/front_right_lower_leg_collision.stl"/>
      </geometry>
    </collision>
    <inertial>
      <mass value="1.0"/>
      <inertia ixx="0.0" ixy="0.0" ixz="0.0" iyy="0.045" iyz="0.0" izz="0.0"/>
    </inertial>
  </link>
  <joint name="front_right_knee" type="revolute">
    <origin rpy="0 0 0" xyz="0.025 0.000 -0.3205"/>
    <axis xyz="0 1 0"/>
    <parent link="front_right_upper_leg"/>
    <child link="front_right_lower_leg"/>
    <dynamics damping="0.1" friction="0.1"/>
    <limit effort="1000" lower="-2.7929" upper="-0.247563" velocity="1000.00"/>
  </joint>
  <gazebo reference="front_right_lower_leg">
    <sensor name="front_right_lower_leg_contactsensor_sensor" type="contact">
      <always_on>true</always_on>
      <contact>
        <collision>front_right_lower_leg_fixed_joint_lump__front_bump_sensor_collision</collision>
      </contact>
      <plugin filename="libgazebo_ros_bumper.so" name="front_right_lower_leg_plugin">
        <bumperTopicName>front_right_lower_leg_contact</bumperTopicName>
        <frameName>front_right_lower_leg</frameName>
      </plugin>
    </sensor>
  </gazebo>
  <transmission name="front_right_knee_trans">
    <type>transmission_interface/SimpleTransmission</type>
    <joint name="front_right_knee">
      <hardwareInterface>EffortJointInterface</hardwareInterface>
    </joint>
    <actuator name="front_right_knee">
      <mechanicalReduction>50</mechanicalReduction>
      <hardwareInterface>EffortJointInterface</hardwareInterface>
    </actuator>
  </transmission>
  <!-- Rear Left -->
  <link name="rear_left_hip">
    <visual>
      <geometry>
        <mesh filename="package://spot_description/meshes/body/rear_left_hip.dae"/>
      </geometry>
    </visual>
    <collision>
      <geometry>
        <mesh filename="package://spot_description/meshes/body/rear_left_hip_collision.stl"/>
      </geometry>
    </collision>
    <inertial>
      <mass value="1.5"/>
      <inertia ixx="0.0605" ixy="0.0" ixz="0.0" iyy="0.0" iyz="0.0" izz="0.0"/>
    </inertial>
  </link>
  <joint name="rear_left_hip_x" type="revolute">
    <origin rpy="0 0 0" xyz="-0.29785 0.05500 0.00000"/>
    <axis xyz="1 0 0"/>
    <parent link="body"/>
    <child link="rear_left_hip"/>
    <dynamics damping="0.1" friction="0.1"/>
    <limit effort="1000" lower="-0.78539816339744827899" upper="0.78539816339744827899" velocity="1000.00"/>
  </joint>
  <transmission name="rear_left_hip_x_trans">
    <type>transmission_interface/SimpleTransmission</type>
    <joint name="rear_left_hip_x">
      <hardwareInterface>EffortJointInterface</hardwareInterface>
    </joint>
    <actuator name="rear_left_hip_x">
      <mechanicalReduction>50</mechanicalReduction>
      <hardwareInterface>EffortJointInterface</hardwareInterface>
    </actuator>
  </transmission>
  <link name="rear_left_upper_leg">
    <visual>
      <geometry>
        <mesh filename="package://spot_description/meshes/body/rear_left_upper_leg.dae"/>
      </geometry>
    </visual>
    <collision>
      <geometry>
        <mesh filename="package://spot_description/meshes/body/rear_left_upper_leg_collision.stl"/>
      </geometry>
    </collision>
    <inertial>
      <mass value="1.5"/>
      <inertia ixx="0.0" ixy="0.0" ixz="0.0" iyy="0.05" iyz="0.0" izz="0.0"/>
    </inertial>
  </link>
  <joint name="rear_left_hip_y" type="revolute">
    <origin rpy="0 0 0" xyz="0.0 0.110945 0.0"/>
    <axis xyz="0 1 0"/>
    <parent link="rear_left_hip"/>
    <child link="rear_left_upper_leg"/>
    <dynamics damping="0.1" friction="0.1"/>
    <limit effort="1000" lower="-0.89884456477707963539" upper="2.2951079663725435509" velocity="1000.00"/>
  </joint>
  <transmission name="rear_left_hip_y_trans">
    <type>transmission_interface/SimpleTransmission</type>
    <joint name="rear_left_hip_y">
      <hardwareInterface>EffortJointInterface</hardwareInterface>
    </joint>
    <actuator name="rear_left_hip_y">
      <mechanicalReduction>50</mechanicalReduction>
      <hardwareInterface>EffortJointInterface</hardwareInterface>
    </actuator>
  </transmission>
  <link name="rear_left_lower_leg">
    <visual>
      <geometry>
        <mesh filename="package://spot_description/meshes/body/rear_left_lower_leg.dae"/>
      </geometry>
    </visual>
    <collision>
      <geometry>
        <mesh filename="package://spot_description/meshes/body/rear_left_lower_leg_collision.stl"/>
      </geometry>
    </collision>
    <inertial>
      <mass value="1.0"/>
      <inertia ixx="0.0" ixy="0.0" ixz="0.0" iyy="0.045" iyz="0.0" izz="0.0"/>
    </inertial>
  </link>
  <joint name="rear_left_knee" type="revolute">
    <origin rpy="0 0 0" xyz="0.025 0.000 -0.3205"/>
    <axis xyz="0 1 0"/>
    <parent link="rear_left_upper_leg"/>
    <child link="rear_left_lower_leg"/>
    <dynamics damping="0.1" friction="0.1"/>
    <limit effort="1000" lower="-2.7929" upper="-0.267153" velocity="1000.00"/>
  </joint>
  <gazebo reference="rear_left_lower_leg">
    <sensor name="rear_left_lower_leg_contactsensor_sensor" type="contact">
      <always_on>true</always_on>
      <contact>
        <collision>rear_left_lower_leg_fixed_joint_lump__rear_bump_sensor_collision</collision>
      </contact>
      <plugin filename="libgazebo_ros_bumper.so" name="rear_left_lower_leg_plugin">
        <bumperTopicName>rear_left_lower_leg_contact</bumperTopicName>
        <frameName>rear_left_lower_leg</frameName>
      </plugin>
    </sensor>
  </gazebo>
  <transmission name="rear_left_knee_trans">
    <type>transmission_interface/SimpleTransmission</type>
    <joint name="rear_left_knee">
      <hardwareInterface>EffortJointInterface</hardwareInterface>
    </joint>
    <actuator name="rear_left_knee">
      <mechanicalReduction>50</mechanicalReduction>
      <hardwareInterface>EffortJointInterface</hardwareInterface>
    </actuator>
  </transmission>
  <!-- Rear Right -->
  <link name="rear_right_hip">
    <visual>
      <geometry>
        <mesh filename="package://spot_description/meshes/body/rear_right_hip.dae"/>
      </geometry>
    </visual>
    <collision>
      <geometry>
        <mesh filename="package://spot_description/meshes/body/rear_right_hip_collision.stl"/>
      </geometry>
    </collision>
    <inertial>
      <mass value="1.5"/>
      <inertia ixx="0.0605" ixy="0.0" ixz="0.0" iyy="0.0" iyz="0.0" izz="0.0"/>
    </inertial>
  </link>
  <joint name="rear_right_hip_x" type="revolute">
    <origin rpy="0 0 0" xyz="-0.29785 -0.05500 0.00000"/>
    <axis xyz="1 0 0"/>
    <parent link="body"/>
    <child link="rear_right_hip"/>
    <dynamics damping="0.1" friction="0.1"/>
    <limit effort="1000" lower="-0.78539816339744827899" upper="0.78539816339744827899" velocity="1000.00"/>
  </joint>
  <transmission name="rear_right_hip_x_trans">
    <type>transmission_interface/SimpleTransmission</type>
    <joint name="rear_right_hip_x">
      <hardwareInterface>EffortJointInterface</hardwareInterface>
    </joint>
    <actuator name="rear_right_hip_x">
      <mechanicalReduction>50</mechanicalReduction>
      <hardwareInterface>EffortJointInterface</hardwareInterface>
    </actuator>
  </transmission>
  <link name="rear_right_upper_leg">
    <visual>
      <geometry>
        <mesh filename="package://spot_description/meshes/body/rear_right_upper_leg.dae"/>
      </geometry>
    </visual>
    <collision>
      <geometry>
        <mesh filename="package://spot_description/meshes/body/rear_right_upper_leg_collision.stl"/>
      </geometry>
    </collision>
    <inertial>
      <mass value="1.5"/>
      <inertia ixx="0.0" ixy="0.0" ixz="0.0" iyy="0.05" iyz="0.0" izz="0.0"/>
    </inertial>
  </link>
  <joint name="rear_right_hip_y" type="revolute">
    <origin rpy="0 0 0" xyz="0.0 -0.110945 0.0"/>
    <axis xyz="0 1 0"/>
    <parent link="rear_right_hip"/>
    <child link="rear_right_upper_leg"/>
    <dynamics damping="0.1" friction="0.1"/>
    <limit effort="1000" lower="-0.89884456477707963539" upper="2.2951079663725435509" velocity="1000.00"/>
  </joint>
  <transmission name="rear_right_hip_y_trans">
    <type>transmission_interface/SimpleTransmission</type>
    <joint name="rear_right_hip_y">
      <hardwareInterface>EffortJointInterface</hardwareInterface>
    </joint>
    <actuator name="rear_right_hip_y">
      <mechanicalReduction>50</mechanicalReduction>
      <hardwareInterface>EffortJointInterface</hardwareInterface>
    </actuator>
  </transmission>
  <link name="rear_right_lower_leg">
    <visual>
      <geometry>
        <mesh filename="package://spot_description/meshes/body/rear_right_lower_leg.dae"/>
      </geometry>
    </visual>
    <collision>
      <geometry>
        <mesh filename="package://spot_description/meshes/body/rear_right_lower_leg_collision.stl"/>
      </geometry>
    </collision>
    <inertial>
      <mass value="1.0"/>
      <inertia ixx="0.0" ixy="0.0" ixz="0.0" iyy="0.045" iyz="0.0" izz="0.0"/>
    </inertial>
  </link>
  <joint name="rear_right_knee" type="revolute">
    <origin rpy="0 0 0" xyz="0.025 0.000 -0.3205"/>
    <axis xyz="0 1 0"/>
    <parent link="rear_right_upper_leg"/>
    <child link="rear_right_lower_leg"/>
    <dynamics damping="0.1" friction="0.1"/>
    <limit effort="1000" lower="-2.7929" upper="-0.257725" velocity="1000.00"/>
  </joint>
  <gazebo reference="rear_right_lower_leg">
    <sensor name="rear_right_lower_leg_contactsensor_sensor" type="contact">
      <always_on>true</always_on>
      <contact>
        <collision>rear_right_lower_leg_fixed_joint_lump__rear_bump_sensor_collision</collision>
      </contact>
      <plugin filename="libgazebo_ros_bumper.so" name="rear_right_lower_leg_plugin">
        <bumperTopicName>rear_right_lower_leg_contact</bumperTopicName>
        <frameName>rear_right_lower_leg</frameName>
      </plugin>
    </sensor>
  </gazebo>
  <transmission name="rear_right_knee_trans">
    <type>transmission_interface/SimpleTransmission</type>
    <joint name="rear_right_knee">
      <hardwareInterface>EffortJointInterface</hardwareInterface>
    </joint>
    <actuator name="rear_right_knee">
      <mechanicalReduction>50</mechanicalReduction>
      <hardwareInterface>EffortJointInterface</hardwareInterface>
    </actuator>
  </transmission>
  <gazebo>
    <plugin filename="libgazebo_ros_control.so" name="gazebo_ros_control"/>
  </gazebo>
  <!-- Original STLs at https://utexas.app.box.com/folder/226702516436 -->
  <link name="realsense_mount_chin">
    <visual name="realsense_mount_chin_visual">
      <geometry>
        <mesh filename="package://spot_description/meshes/realsense/chin.dae"/>
      </geometry>
    </visual>
    <collision name="realsense_mount_chin_collision">
      <geometry>
        <mesh filename="package://spot_description/meshes/realsense/chin.dae"/>
      </geometry>
    </collision>
  </link>
  <joint name="joint_chin_to_arm" type="fixed">
    <parent link="arm0_wrist_roll"/>
    <child link="realsense_mount_chin"/>
    <origin rpy="3.1416 0 -1.57" xyz="0.145 0 -0.06"/>
  </joint>
  <link name="realsense_mount_chin_top">
    <visual name="realsense_mount_chin_top_visual">
      <geometry>
        <mesh filename="package://spot_description/meshes/realsense/chin_top.dae"/>
      </geometry>
    </visual>
    <collision name="realsense_mount_chin_collision">
      <geometry>
        <mesh filename="package://spot_description/meshes/realsense/chin_top.dae"/>
      </geometry>
    </collision>
  </link>
  <joint name="joint_chin_to_chip_top" type="fixed">
    <parent link="realsense_mount_chin"/>
    <child link="realsense_mount_chin_top"/>
    <origin rpy="1.57 3.14 0" xyz="0 -0.008 -0.025"/>
  </joint>
  <link name="realsense_mount_slider">
    <visual name="realsense_mount_slider_visual">
      <geometry>
        <mesh filename="package://spot_description/meshes/realsense/slider_reg.dae"/>
      </geometry>
    </visual>
    <collision name="realsense_mount_slider_collision">
      <geometry>
        <mesh filename="package://spot_description/meshes/realsense/slider_reg.dae"/>
      </geometry>
    </collision>
  </link>
  <joint name="joint_slider_to_mount" type="fixed">
    <parent link="realsense_mount_chin"/>
    <child link="realsense_mount_slider"/>
    <origin rpy="0 -1.57 0" xyz="0 0.01 0.03"/>
  </joint>
  <link name="realsense_camera_mount">
    <visual name="realsense_camera_mount_visual">
      <geometry>
        <mesh filename="package://spot_description/meshes/realsense/camera_interface.dae"/>
      </geometry>
    </visual>
    <collision name="realsense_camera_mount_collision">
      <geometry>
        <mesh filename="package://spot_description/meshes/realsense/camera_interface.dae"/>
      </geometry>
    </collision>
  </link>
  <joint name="joint_interface_to_slider" type="fixed">
    <parent link="realsense_mount_slider"/>
    <child link="realsense_camera_mount"/>
    <origin rpy="0 -1.57 1.57" xyz="0.0225 -0.0325 0"/>
  </joint>
  <material name="aluminum">
    <color rgba="0.5 0.5 0.5 1"/>
  </material>
  <material name="plastic">
    <color rgba="0.1 0.1 0.1 1"/>
  </material>
  <!-- camera body, with origin at bottom screw mount -->
  <joint name="camera_joint" type="fixed">
    <origin rpy="0 -1.57 1.57" xyz="0 0.0125 0.01"/>
    <parent link="realsense_camera_mount"/>
    <child link="camera_bottom_screw_frame"/>
  </joint>
  <link name="camera_bottom_screw_frame"/>
  <joint name="camera_link_joint" type="fixed">
    <origin rpy="0 0 0" xyz="0.010600000000000002 0.0175 0.0125"/>
    <parent link="camera_bottom_screw_frame"/>
    <child link="camera_link"/>
  </joint>
  <link name="camera_link">
    <visual>
      <!-- the mesh origin is at front plate in between the two infrared camera axes -->
      <origin rpy="1.5707963267948966 0 1.5707963267948966" xyz="0.0043 -0.0175 0"/>
      <geometry>
        <mesh filename="package://realsense2_description/meshes/d435.dae"/>
      </geometry>
    </visual>
    <collision>
      <origin rpy="0 0 0" xyz="0 -0.0175 0"/>
      <geometry>
        <box size="0.02505 0.09 0.025"/>
      </geometry>
    </collision>
    <inertial>
      <!-- The following are not reliable values, and should not be used for modeling -->
      <mass value="0.072"/>
      <origin xyz="0 0 0"/>
      <inertia ixx="0.003881243" ixy="0.0" ixz="0.0" iyy="0.000498940" iyz="0.0" izz="0.003879257"/>
    </inertial>
  </link>
  <!-- camera depth joints and links -->
  <joint name="camera_depth_joint" type="fixed">
    <origin rpy="0 0 0" xyz="0 0 0"/>
    <parent link="camera_link"/>
    <child link="camera_depth_frame"/>
  </joint>
  <link name="camera_depth_frame"/>
  <joint name="camera_depth_optical_joint" type="fixed">
    <origin rpy="-1.5707963267948966 0 -1.5707963267948966" xyz="0 0 0"/>
    <parent link="camera_depth_frame"/>
    <child link="camera_depth_optical_frame"/>
  </joint>
  <link name="camera_depth_optical_frame"/>
  <!-- camera left IR joints and links -->
  <joint name="camera_infra1_joint" type="fixed">
    <origin rpy="0 0 0" xyz="0 0.0 0"/>
    <parent link="camera_link"/>
    <child link="camera_infra1_frame"/>
  </joint>
  <link name="camera_infra1_frame"/>
  <joint name="camera_infra1_optical_joint" type="fixed">
    <origin rpy="-1.5707963267948966 0 -1.5707963267948966" xyz="0 0 0"/>
    <parent link="camera_infra1_frame"/>
    <child link="camera_infra1_optical_frame"/>
  </joint>
  <link name="camera_infra1_optical_frame"/>
  <!-- camera right IR joints and links -->
  <joint name="camera_infra2_joint" type="fixed">
    <origin rpy="0 0 0" xyz="0 -0.05 0"/>
    <parent link="camera_link"/>
    <child link="camera_infra2_frame"/>
  </joint>
  <link name="camera_infra2_frame"/>
  <joint name="camera_infra2_optical_joint" type="fixed">
    <origin rpy="-1.5707963267948966 0 -1.5707963267948966" xyz="0 0 0"/>
    <parent link="camera_infra2_frame"/>
    <child link="camera_infra2_optical_frame"/>
  </joint>
  <link name="camera_infra2_optical_frame"/>
  <!-- camera color joints and links -->
  <joint name="camera_color_joint" type="fixed">
    <origin rpy="0 0 0" xyz="0 0.015 0"/>
    <parent link="camera_link"/>
    <child link="camera_color_frame"/>
  </joint>
  <link name="camera_color_frame"/>
  <joint name="camera_color_optical_joint" type="fixed">
    <origin rpy="-1.5707963267948966 0 -1.5707963267948966" xyz="0 0 0"/>
    <parent link="camera_color_frame"/>
    <child link="camera_color_optical_frame"/>
  </joint>
  <link name="camera_color_optical_frame"/>
  <!-- This file is a placeholder which is included by default from
       spot.urdf.xacro. If a robot is being customized and requires
       additional URDF, set the SPOT_URDF_EXTRAS environment variable
       to the full path of the file you would like included. -->
  <!-- Transmissions -->
  <transmission name="tran1">
    <type>transmission_interface/SimpleTransmission</type>
    <joint name="arm0_shoulder_yaw">
      <hardwareInterface>hardware_interface/PositionJointInterface</hardwareInterface>
    </joint>
    <actuator name="motor1">
      <hardwareInterface>hardware_interface/PositionJointInterface</hardwareInterface>
      <mechanicalReduction>1</mechanicalReduction>
    </actuator>
  </transmission>
  <transmission name="tran2">
    <type>transmission_interface/SimpleTransmission</type>
    <joint name="arm0_shoulder_pitch">
      <hardwareInterface>hardware_interface/PositionJointInterface</hardwareInterface>
    </joint>
    <actuator name="motor2">
      <hardwareInterface>hardware_interface/PositionJointInterface</hardwareInterface>
      <mechanicalReduction>1</mechanicalReduction>
    </actuator>
  </transmission>
  <transmission name="tran3">
    <type>transmission_interface/SimpleTransmission</type>
    <joint name="arm0_elbow_pitch">
      <hardwareInterface>hardware_interface/PositionJointInterface</hardwareInterface>
    </joint>
    <actuator name="motor3">
      <hardwareInterface>hardware_interface/PositionJointInterface</hardwareInterface>
      <mechanicalReduction>1</mechanicalReduction>
    </actuator>
  </transmission>
  <transmission name="tran4">
    <type>transmission_interface/SimpleTransmission</type>
    <joint name="arm0_elbow_roll">
      <hardwareInterface>hardware_interface/PositionJointInterface</hardwareInterface>
    </joint>
    <actuator name="motor4">
      <hardwareInterface>hardware_interface/PositionJointInterface</hardwareInterface>
      <mechanicalReduction>1</mechanicalReduction>
    </actuator>
  </transmission>
  <transmission name="tran5">
    <type>transmission_interface/SimpleTransmission</type>
    <joint name="arm0_wrist_pitch">
      <hardwareInterface>hardware_interface/PositionJointInterface</hardwareInterface>
    </joint>
    <actuator name="motor5">
      <hardwareInterface>hardware_interface/PositionJointInterface</hardwareInterface>
      <mechanicalReduction>1</mechanicalReduction>
    </actuator>
  </transmission>
  <transmission name="tran6">
    <type>transmission_interface/SimpleTransmission</type>
    <joint name="arm0_wrist_roll">
      <hardwareInterface>hardware_interface/PositionJointInterface</hardwareInterface>
    </joint>
    <actuator name="motor6">
      <hardwareInterface>hardware_interface/PositionJointInterface</hardwareInterface>
      <mechanicalReduction>1</mechanicalReduction>
    </actuator>
  </transmission>
  <!-- EOF Transmissions -->
  <link name="arm0_base_link"/>
  <link name="arm0_shoulder_yaw">
    <visual>
      <origin rpy="0 0 0" xyz="0 0 0"/>
      <geometry>
        <mesh filename="package://spot_description/meshes/arm/arm0.link_sh0.obj"/>
      </geometry>
      <material name="arm0.link_sh0">
        <color rgba="0.2 0.2 0.2 1"/>
      </material>
    </visual>
    <collision>
      <origin rpy="0 0 0" xyz="0 0 0"/>
      <geometry>
        <mesh filename="package://spot_description/meshes/arm/arm0.link_sh0.obj"/>
      </geometry>
      <material name="arm0.link_sh0">
        <color rgba="1 0.2 0.2 1"/>
      </material>
    </collision>
  </link>
  <joint name="arm0_shoulder_yaw" type="revolute">
    <origin rpy="0 0 0" xyz="0 0 0"/>
    <axis xyz="0 0 1"/>
    <parent link="arm0_base_link"/>
    <child link="arm0_shoulder_yaw"/>
    <limit effort="1000" lower="-2.61799387799149441136" upper="3.14159265358979311599" velocity="1000.00"/>
  </joint>
  <link name="arm0_shoulder_pitch">
    <visual>
      <origin rpy="0 0 0" xyz="0 0 0"/>
      <geometry>
        <mesh filename="package://spot_description/meshes/arm/arm0.link_sh1.obj"/>
      </geometry>
      <material name="arm0.link_sh1">
        <color rgba="0.2 0.2 0.2 1"/>
      </material>
    </visual>
    <collision>
      <origin rpy="0 0 0" xyz="0 0 0"/>
      <geometry>
        <mesh filename="package://spot_description/meshes/arm/arm0.link_sh1.obj"/>
      </geometry>
      <material name="arm0.link_sh1">
        <color rgba="1 0.2 0.2 1"/>
      </material>
    </collision>
  </link>
  <joint name="arm0_shoulder_pitch" type="revolute">
    <origin rpy="0 0 0" xyz="0.0 0.0 0.0"/>
    <axis xyz="0 1 0"/>
    <parent link="arm0_shoulder_yaw"/>
    <child link="arm0_shoulder_pitch"/>
    <limit effort="1000" lower="-3.14159265358979311599" upper="0.52359877559829881565" velocity="1000.00"/>
  </joint>
  <link name="arm0_shoulder_roll">
    <visual>
      <origin rpy="0 0 0" xyz="0 0 0"/>
      <geometry>
        <mesh filename="package://spot_description/meshes/arm/arm0.link_hr0.obj"/>
      </geometry>
      <material name="arm0.link_hr0">
        <color rgba="0.2 0.2 0.2 1"/>
      </material>
    </visual>
    <collision>
      <origin rpy="0 0 0" xyz="0 0 0"/>
      <geometry>
        <mesh filename="package://spot_description/meshes/arm/arm0.link_hr0.obj"/>
      </geometry>
      <material name="arm0.link_hr0">
        <color rgba="1 0.2 0.2 1"/>
      </material>
    </collision>
  </link>
  <joint name="arm0_shoulder_roll" type="fixed">
    <origin rpy="0 0 0" xyz="0.0 0.0 0.0"/>
    <axis xyz="1 0 0"/>
    <parent link="arm0_shoulder_pitch"/>
    <child link="arm0_shoulder_roll"/>
    <limit effort="0" lower="0" upper="0" velocity="0"/>
  </joint>
  <link name="arm0_elbow_pitch">
    <visual>
      <origin rpy="0 0 0" xyz="0 0 0"/>
      <geometry>
        <mesh filename="package://spot_description/meshes/arm/arm0.link_el0.obj"/>
      </geometry>
      <material name="arm0.link_el0">
        <color rgba="0.2 0.2 0.2 1"/>
      </material>
    </visual>
    <collision>
      <origin rpy="0 0 0" xyz="0 0 0"/>
      <geometry>
        <mesh filename="package://spot_description/meshes/arm/arm0.link_el0.obj"/>
      </geometry>
      <material name="arm0.link_el0">
        <color rgba="1 0.2 0.2 1"/>
      </material>
    </collision>
  </link>
  <joint name="arm0_elbow_pitch" type="revolute">
    <origin rpy="0 0 0" xyz="0.3385 0 0"/>
    <axis xyz="0 1 0"/>
    <parent link="arm0_shoulder_roll"/>
    <child link="arm0_elbow_pitch"/>
    <limit effort="1000" lower="0" upper="3.14159265358979311599" velocity="1000.00"/>
  </joint>
  <link name="arm0_elbow_roll">
    <visual>
      <origin rpy="0 0 0" xyz="0 0 0"/>
      <geometry>
        <mesh filename="package://spot_description/meshes/arm/arm0.link_el1.obj"/>
      </geometry>
      <material name="arm0.link_el1">
        <color rgba="0.2 0.2 0.2 1"/>
      </material>
    </visual>
    <collision>
      <origin rpy="0 0 0" xyz="0 0 0"/>
      <geometry>
        <mesh filename="package://spot_description/meshes/arm/arm0.link_el1.obj"/>
      </geometry>
      <material name="arm0.link_el1">
        <color rgba="1 0.2 0.2 1"/>
      </material>
    </collision>
  </link>
  <joint name="arm0_elbow_roll" type="revolute">
    <origin rpy="0 0 0" xyz="0.40330 0.0 0.0750"/>
    <axis xyz="1 0 0"/>
    <parent link="arm0_elbow_pitch"/>
    <child link="arm0_elbow_roll"/>
    <limit effort="1000" lower="-2.79252680319092716487" upper="2.79252680319092716487" velocity="1000.00"/>
  </joint>
  <link name="arm0_wrist_pitch">
    <visual>
      <origin rpy="0 0 0" xyz="0 0 0"/>
      <geometry>
        <mesh filename="package://spot_description/meshes/arm/arm0.link_wr0.obj"/>
      </geometry>
      <material name="arm0.link_wr0">
        <color rgba="0.2 0.2 0.2 1"/>
      </material>
    </visual>
    <collision>
      <origin rpy="0 0 0" xyz="0 0 0"/>
      <geometry>
        <mesh filename="package://spot_description/meshes/arm/arm0.link_wr0.obj"/>
      </geometry>
      <material name="arm0.link_wr0">
        <color rgba="1 0.2 0.2 1"/>
      </material>
    </collision>
  </link>
  <joint name="arm0_wrist_pitch" type="revolute">
    <origin rpy="0 0 0" xyz="0.0 0.0 0.0"/>
    <axis xyz="0 1 0"/>
    <parent link="arm0_elbow_roll"/>
    <child link="arm0_wrist_pitch"/>
    <limit effort="1000" lower="-1.83259571459404613236" upper="1.83259571459404613236" velocity="1000.00"/>
  </joint>
  <link name="arm0_wrist_roll">
    <visual>
      <origin rpy="0 0 0" xyz="0 0 0"/>
      <geometry>
        <mesh filename="package://spot_description/meshes/arm/arm0.link_wr1.obj"/>
      </geometry>
      <material name="arm0.link_wr1">
        <color rgba="0.2 0.2 0.2 1"/>
      </material>
    </visual>
    <collision>
      <origin rpy="0 0 0" xyz="0 0 0"/>
      <geometry>
        <mesh filename="package://spot_description/meshes/arm/arm0.link_wr1.obj"/>
      </geometry>
      <material name="arm0.link_wr1">
        <color rgba="1 0.2 0.2 1"/>
      </material>
    </collision>
  </link>
  <joint name="arm0_wrist_roll" type="revolute">
    <origin rpy="0 0 0" xyz="0.0 0.0 0.0"/>
    <axis xyz="1 0 0"/>
    <parent link="arm0_wrist_pitch"/>
    <child link="arm0_wrist_roll"/>
    <limit effort="1000" lower="-2.87979326579064354163" upper="2.87979326579064354163" velocity="1000.00"/>
  </joint>
  <link name="arm0_fingers">
    <visual>
      <origin rpy="0 0 0" xyz="0 0 0"/>
      <geometry>
        <mesh filename="package://spot_description/meshes/arm/arm0.link_fngr.obj"/>
      </geometry>
      <material name="arm0.link_fngr">
        <color rgba="0.2 0.2 0.2 1"/>
      </material>
    </visual>
    <collision>
      <origin rpy="0 0 0" xyz="0 0 0"/>
      <geometry>
        <mesh filename="package://spot_description/meshes/arm/arm0.link_fngr.obj"/>
      </geometry>
      <material name="arm0.link_fngr">
        <color rgba="0.2 0.2 0.2 1"/>
      </material>
    </collision>
  </link>
  <joint name="arm0_fingers" type="revolute">
    <origin rpy="0 0 0" xyz="0.11745 0 0.014820"/>
    <axis xyz="0.0 1.0 0.0"/>
    <parent link="arm0_wrist_roll"/>
    <child link="arm0_fingers"/>
    <limit effort="1000" lower="-1.57" upper="0.0" velocity="1000.00"/>
  </joint>
  <link name="arm0.link_wr1"/>
  <joint name="arm0_link_wr1_to_wrist" type="fixed">
    <parent link="arm0_wrist_roll"/>
    <child link="arm0.link_wr1"/>
    <origin xyz="0 0 0"/>
  </joint>
  <link name="hand_color_image_sensor"/>
  <joint name="color_image_joint" type="fixed">
    <parent link="arm0_wrist_roll"/>
    <child link="hand_color_image_sensor"/>
    <origin rpy="-1.57 0 -1.54" xyz="0.14 0.02 0.022"/>
  </joint>
  <joint name="arm0_mount" type="fixed">
    <origin rpy="0 0 0" xyz="0.292 0 0.188"/>
    <parent link="base_link"/>
    <child link="arm0_base_link"/>
  </joint>
</robot>
